Workbook

Sheet biomass_quality
B1: Fuel and heating rate | C1: Pine wood 10 | D1: Pine wood 20 | E1: Pine wood 30 | F1: Kiwi 10 | G1: Kiwi 20 | H1: Kiwi 30 | I1: Kiwi N2 10 | J1: Kiwi N2 20 | K1: Kiwi N2 30 | L1: Kiwi N3 10 | M1: Kiwi N3 20 | N1: Kiwi N3 30 | O1: Gorse 10 | P1: Gorse 20 | Q1: Gorse 30 | R1: Gorse N2 10 | S1: Gorse N2 20 | T1: Gorse N2 30 | U1: Gorse N3 10 | V1: Gorse N3 20 | W1: Gorse N3 30 | X1: Poultry 10 | Y1: Poultry 20 | Z1: Poultry 30 | AA1: Turkey 10 | AB1: Turkey 20 | AC1: Turkey 30
A2: XRF Ash analysis | B2: Na | C2: 0.007 | D2: 0.007 | E2: 0.007 | F2: 0.072 | G2: 0.072 | H2: 0.072 | I2: 0.077 | J2: 0.077 | K2: 0.077 | L2: 0.13 | M2: 0.13 | N2: 0.13 | O2: 0.116 | P2: 0.116 | Q2: 0.116 | R2: 0.009 | S2: 0.009 | T2: 0.009 | U2: 0.01 | V2: 0.01 | W2: 0.01 | X2: 0 | Y2: 0 | Z2: 0 | AA2: 0 | AB2: 0 | AC2: 0
B3: Mg | C3: 0.155 | D3: 0.155 | E3: 0.155 | F3: 0.08 | G3: 0.08 | H3: 0.08 | I3: 0.048 | J3: 0.048 | K3: 0.048 | L3: 0.068 | M3: 0.068 | N3: 0.068 | O3: 0.072 | P3: 0.072 | Q3: 0.072 | R3: 0.04 | S3: 0.04 | T3: 0.04 | U3: 0.037 | V3: 0.037 | W3: 0.037 | X3: 0 | Y3: 0 | Z3: 0 | AA3: 0 | AB3: 0 | AC3: 0
B4: Al | C4: 0.22 | D4: 0.22 | E4: 0.22 | F4: 0.106 | G4: 0.106 | H4: 0.106 | I4: 0.118 | J4: 0.118 | K4: 0.118 | L4: 0.023 | M4: 0.023 | N4: 0.023 | O4: 0.044 | P4: 0.044 | Q4: 0.044 | R4: 0.104 | S4: 0.104 | T4: 0.104 | U4: 0.043 | V4: 0.043 | W4: 0.043 | X4: 0.005 | Y4: 0.005 | Z4: 0.005 | AA4: 0.003 | AB4: 0.003 | AC4: 0.003
B5: Si | C5: 0.114 | D5: 0.114 | E5: 0.114 | F5: 0 | G5: 0 | H5: 0 | I5: 0.34 | J5: 0.34 | K5: 0.34 | L5: 0.097 | M5: 0.097 | N5: 0.097 | O5: 0.117 | P5: 0.117 | Q5: 0.117 | R5: 0.312 | S5: 0.312 | T5: 0.312 | U5: 0.154 | V5: 0.154 | W5: 0.154 | X5: 0.016 | Y5: 0.016 | Z5: 0.016 | AA5: 0.012 | AB5: 0.012 | AC5: 0.012
B6: P | C6: 0.01 | D6: 0.01 | E6: 0.01 | F6: 0.032 | G6: 0.032 | H6: 0.032 | I6: 0.014 | J6: 0.014 | K6: 0.014 | L6: 0.026 | M6: 0.026 | N6: 0.026 | O6: 0.028 | P6: 0.028 | Q6: 0.028 | R6: 0.025 | S6: 0.025 | T6: 0.025 | U6: 0.022 | V6: 0.022 | W6: 0.022 | X6: 0.175 | Y6: 0.175 | Z6: 0.175 | AA6: 0.271 | AB6: 0.271 | AC6: 0.271
B7: S | C7: 0.031 | D7: 0.031 | E7: 0.031 | F7: 0.062 | G7: 0.062 | H7: 0.062 | I7: 0.037 | J7: 0.037 | K7: 0.037 | L7: 0.06 | M7: 0.06 | N7: 0.06 | O7: 0.055 | P7: 0.055 | Q7: 0.055 | R7: 0.019 | S7: 0.019 | T7: 0.019 | U7: 0.018 | V7: 0.018 | W7: 0.018 | X7: 0.047 | Y7: 0.047 | Z7: 0.047 | AA7: 0.049 | AB7: 0.049 | AC7: 0.049
B8: Cl | C8: 0.011 | D8: 0.011 | E8: 0.011 | F8: 0.08 | G8: 0.08 | H8: 0.08 | I8: 0.028 | J8: 0.028 | K8: 0.028 | L8: 0.057 | M8: 0.057 | N8: 0.057 | O8: 0.036 | P8: 0.036 | Q8: 0.036 | R8: 0.003 | S8: 0.003 | T8: 0.003 | U8: 0.004 | V8: 0.004 | W8: 0.004 | X8: 0.198 | Y8: 0.198 | Z8: 0.198 | AA8: 0.159 | AB8: 0.159 | AC8: 0.159
B9: K | C9: 0.213 | D9: 0.213 | E9: 0.213 | F9: 0.315 | G9: 0.315 | H9: 0.315 | I9: 0.147 | J9: 0.147 | K9: 0.147 | L9: 0.254 | M9: 0.254 | N9: 0.254 | O9: 0.268 | P9: 0.268 | Q9: 0.268 | R9: 0.211 | S9: 0.211 | T9: 0.211 | U9: 0.182 | V9: 0.182 | W9: 0.182 | X9: 0.382 | Y9: 0.382 | Z9: 0.382 | AA9: 0.316 | AB9: 0.316 | AC9: 0.316
B10: Ca | C10: 0.19 | D10: 0.19 | E10: 0.19 | F10: 0.21 | G10: 0.21 | H10: 0.21 | I10: 0.124 | J10: 0.124 | K10: 0.124 | L10: 0.222 | M10: 0.222 | N10: 0.222 | O10: 0.18 | P10: 0.18 | Q10: 0.18 | R10: 0.235 | S10: 0.235 | T10: 0.235 | U10: 0.499 | V10: 0.499 | W10: 0.499 | X10: 0.149 | Y10: 0.149 | Z10: 0.149 | AA10: 0.176 | AB10: 0.176 | AC10: 0.176
B11: Ti | C11: 0.002 | D11: 0.002 | E11: 0.002 | F11: 0 | G11: 0 | H11: 0 | I11: 0.001 | J11: 0.001 | K11: 0.001 | L11: 0.001 | M11: 0.001 | N11: 0.001 | O11: 0.004 | P11: 0.004 | Q11: 0.004 | R11: 0.002 | S11: 0.002 | T11: 0.002 | U11: 0.001 | V11: 0.001 | W11: 0.001 | X11: 0 | Y11: 0 | Z11: 0 | AA11: 0 | AB11: 0 | AC11: 0
B12: Mn | C12: 0.019 | D12: 0.019 | E12: 0.019 | F12: 0.011 | G12: 0.011 | H12: 0.011 | I12: 0.018 | J12: 0.018 | K12: 0.018 | L12: 0.024 | M12: 0.024 | N12: 0.024 | O12: 0.022 | P12: 0.022 | Q12: 0.022 | R12: 0.003 | S12: 0.003 | T12: 0.003 | U12: 0.002 | V12: 0.002 | W12: 0.002 | X12: 0.009 | Y12: 0.009 | Z12: 0.009 | AA12: 0.004 | AB12: 0.004 | AC12: 0.004
B13: Fe | C13: 0.021 | D13: 0.021 | E13: 0.021 | F13: 0.026 | G13: 0.026 | H13: 0.026 | I13: 0.046 | J13: 0.046 | K13: 0.046 | L13: 0.035 | M13: 0.035 | N13: 0.035 | O13: 0.045 | P13: 0.045 | Q13: 0.045 | R13: 0.034 | S13: 0.034 | T13: 0.034 | U13: 0.025 | V13: 0.025 | W13: 0.025 | X13: 0.01 | Y13: 0.01 | Z13: 0.01 | AA13: 0.007 | AB13: 0.007 | AC13: 0.007
B14: Zn | C14: 0.002 | D14: 0.002 | E14: 0.002 | F14: 0.002 | G14: 0.002 | H14: 0.002 | I14: 0.002 | J14: 0.002 | K14: 0.002 | L14: 0.004 | M14: 0.004 | N14: 0.004 | O14: 0.003 | P14: 0.003 | Q14: 0.003 | R14: 0.003 | S14: 0.003 | T14: 0.003 | U14: 0.002 | V14: 0.002 | W14: 0.002 | X14: 0.007 | Y14: 0.007 | Z14: 0.007 | AA14: 0.004 | AB14: 0.004 | AC14: 0.004
A15: Ultimate analysis | B15: N | C15: 0.001 | D15: 0.001 | E15: 0.001 | F15: 0.01 | G15: 0.01 | H15: 0.01 | I15: 0.008 | J15: 0.008 | K15: 0.008 | L15: 0.008 | M15: 0.008 | N15: 0.008 | O15: 0.011 | P15: 0.011 | Q15: 0.011 | R15: 0.013 | S15: 0.013 | T15: 0.013 | U15: 0.007 | V15: 0.007 | W15: 0.007 | X15: 0.026 | Y15: 0.026 | Z15: 0.026 | AA15: 0.05 | AB15: 0.05 | AC15: 0.05
B16: C | C16: 0.472 | D16: 0.472 | E16: 0.472 | F16: 0.47 | G16: 0.47 | H16: 0.47 | I16: 0.449 | J16: 0.449 | K16: 0.449 | L16: 0.453 | M16: 0.453 | N16: 0.453 | O16: 0.495 | P16: 0.495 | Q16: 0.495 | R16: 0.474 | S16: 0.474 | T16: 0.474 | U16: 0.444 | V16: 0.444 | W16: 0.444 | X16: 0.419 | Y16: 0.419 | Z16: 0.419 | AA16: 0.383 | AB16: 0.383 | AC16: 0.383
B17: H | C17: 0.063 | D17: 0.063 | E17: 0.063 | F17: 0.055 | G17: 0.055 | H17: 0.055 | I17: 0.061 | J17: 0.061 | K17: 0.061 | L17: 0.062 | M17: 0.062 | N17: 0.062 | O17: 0.061 | P17: 0.061 | Q17: 0.061 | R17: 0.078 | S17: 0.078 | T17: 0.078 | U17: 0.076 | V17: 0.076 | W17: 0.076 | X17: 0.043 | Y17: 0.043 | Z17: 0.043 | AA17: 0.04 | AB17: 0.04 | AC17: 0.04
B18: O | C18: 0.46 | D18: 0.46 | E18: 0.46 | F18: 0.465 | G18: 0.465 | H18: 0.465 | I18: 0.482 | J18: 0.482 | K18: 0.482 | L18: 0.477 | M18: 0.477 | N18: 0.477 | O18: 0.433 | P18: 0.433 | Q18: 0.433 | R18: 0.435 | S18: 0.435 | T18: 0.435 | U18: 0.473 | V18: 0.473 | W18: 0.473 | X18: 0.512 | Y18: 0.512 | Z18: 0.512 | AA18: 0.528 | AB18: 0.528 | AC18: 0.528
A19: Heating values [MJ/kg] | B19: HHV | C19: 19.1 | D19: 19.1 | E19: 19.1 | F19: 18.1 | G19: 18.1 | H19: 18.1 | I19: 17.9 | J19: 17.9 | K19: 17.9 | L19: 18.2 | M19: 18.2 | N19: 18.2 | O19: 20 | P19: 20 | Q19: 20 | R19: 21.2 | S19: 21.2 | T19: 21.2 | U19: 19.6 | V19: 19.6 | W19: 19.6 | X19: 14.4 | Y19: 14.4 | Z19: 14.4 | AA19: 12.5 | AB19: 12.5 | AC19: 12.5
B20: LHV | C20: 17.8 | D20: 17.8 | E20: 17.8 | F20: 16.9 | G20: 16.9 | H20: 16.9 | I20: 16.5 | J20: 16.5 | K20: 16.5 | L20: 16.8 | M20: 16.8 | N20: 16.8 | O20: 18.7 | P20: 18.7 | Q20: 18.7 | R20: 19.5 | S20: 19.5 | T20: 19.5 | U20: 17.9 | V20: 17.9 | W20: 17.9 | X20: 13.4 | Y20: 13.4 | Z20: 13.4 | AA20: 11.7 | AB20: 11.7 | AC20: 11.7
A21: Proximate analysis | B21: Moisture | C21: 0.052 | D21: 0.052 | E21: 0.052 | F21: 0.085 | G21: 0.085 | H21: 0.085 | I21: 0.094 | J21: 0.094 | K21: 0.094 | L21: 0.092 | M21: 0.092 | N21: 0.092 | O21: 0.098 | P21: 0.098 | Q21: 0.098 | R21: 0.072 | S21: 0.072 | T21: 0.072 | U21: 0.074 | V21: 0.074 | W21: 0.074 | X21: 0.266 | Y21: 0.266 | Z21: 0.266 | AA21: 0.327 | AB21: 0.327 | AC21: 0.327
B22: Volatile matter | C22: 0.716 | D22: 0.716 | E22: 0.716 | F22: 0.714 | G22: 0.714 | H22: 0.714 | I22: 0.604 | J22: 0.604 | K22: 0.604 | L22: 0.602 | M22: 0.602 | N22: 0.602 | O22: 0.723 | P22: 0.723 | Q22: 0.723 | R22: 0.731 | S22: 0.731 | T22: 0.731 | U22: 0.727 | V22: 0.727 | W22: 0.727 | X22: 0.477 | Y22: 0.477 | Z22: 0.477 | AA22: 0.459 | AB22: 0.459 | AC22: 0.459
B23: Fixed carbon | C23: 0.228 | D23: 0.228 | E23: 0.228 | F23: 0.158 | G23: 0.158 | H23: 0.158 | I23: 0.248 | J23: 0.248 | K23: 0.248 | L23: 0.245 | M23: 0.245 | N23: 0.245 | O23: 0.161 | P23: 0.161 | Q23: 0.161 | R23: 0.161 | S23: 0.161 | T23: 0.161 | U23: 0.16 | V23: 0.16 | W23: 0.16 | X23: 0.163 | Y23: 0.163 | Z23: 0.163 | AA23: 0.101 | AB23: 0.101 | AC23: 0.101
B24: Ashes | C24: 0.004 | D24: 0.004 | E24: 0.004 | F24: 0.043 | G24: 0.043 | H24: 0.043 | I24: 0.054 | J24: 0.054 | K24: 0.054 | L24: 0.061 | M24: 0.061 | N24: 0.061 | O24: 0.018 | P24: 0.018 | Q24: 0.018 | R24: 0.037 | S24: 0.037 | T24: 0.037 | U24: 0.039 | V24: 0.039 | W24: 0.039 | X24: 0.096 | Y24: 0.096 | Z24: 0.096 | AA24: 0.114 | AB24: 0.114 | AC24: 0.114
A25: Combustion parameters | B25: Ti [°C] | C25: 283 | D25: 293.4 | E25: 297.3 | F25: 251 | G25: 257.3 | H25: 256 | I25: 251.9 | J25: 256.9 | K25: 254.6 | L25: 251 | M25: 273.8 | N25: 263.7 | O25: 249.2 | P25: 256.1 | Q25: 252.3 | R25: 257.6 | S25: 253.3 | T25: 274.3 | U25: 247.6 | V25: 256.2 | W25: 258.1 | X25: 292.4 | Y25: 247.3 | Z25: 243.9 | AA25: 227.8 | AB25: 233.4 | AC25: 231.5
B26: Tb [°C] | C26: 415.7 | D26: 409.6 | E26: 418.4 | F26: 399.3 | G26: 400.4 | H26: 408.8 | I26: 424.6 | J26: 421.3 | K26: 420.7 | L26: 424.8 | M26: 415 | N26: 435.7 | O26: 429.8 | P26: 425.8 | Q26: 442.4 | R26: 436.1 | S26: 432.8 | T26: 442.3 | U26: 418.8 | V26: 443.9 | W26: 422.3 | X26: 395 | Y26: 396.6 | Z26: 393.3 | AA26: 431.5 | AB26: 439.7 | AC26: 387.6
B27: Tp [°C] | C27: 331 | D27: 352 | E27: 353.2 | F27: 284.3 | G27: 289 | H27: 290 | I27: 283.7 | J27: 294.6 | K27: 292.3 | L27: 282.9 | M27: 324.8 | N27: 332.4 | O27: 294.5 | P27: 303.8 | Q27: 292.5 | R27: 302.7 | S27: 300.1 | T27: 322.9 | U27: 279.4 | V27: 290.1 | W27: 294.1 | X27: 268 | Y27: 275.1 | Z27: 276.8 | AA27: 270.5 | AB27: 270.3 | AC27: 273.3
B28: ΔT1/2 [°C] | C28: 66.3 | D28: 78.1 | E28: 79.4 | F28: 72.3 | G28: 77 | H28: 79.8 | I28: 93.4 | J28: 94.9 | K28: 95.1 | L28: 89.2 | M28: 79.3 | N28: 95.4 | O28: 91.1 | P28: 89.2 | Q28: 93.1 | R28: 88.2 | S28: 90.2 | T28: 85.1 | U28: 91.5 | V28: 97 | W28: 92.5 | X28: 75.4 | Y28: 73.5 | Z28: 72.6 | AA28: 88.4 | AB28: 81.7 | AC28: 71.9
B29: DTGmax | C29: 8 | D29: 13.6 | E29: 22.4 | F29: 5.9 | G29: 10.4 | H29: 15.1 | I29: 4.8 | J29: 9.8 | K29: 15.3 | L29: 5.4 | M29: 12.3 | N29: 14.6 | O29: 4.7 | P29: 9.9 | Q29: 12.8 | R29: 4.9 | S29: 9.8 | T29: 14.3 | U29: 5.3 | V29: 9.4 | W29: 15.1 | X29: 4.8 | Y29: 10.5 | Z29: 15.3 | AA29: 3.3 | AB29: 6.6 | AC29: 16
B30: DTGmean | C30: 1.2 | D30: 1.6 | E30: 2.5 | F30: 1 | G30: 1.6 | H30: 2.4 | I30: 1 | J30: 1.9 | K30: 2.9 | L30: 1.1 | M30: 1.9 | N30: 2.8 | O30: 1 | P30: 2.1 | Q30: 2.7 | R30: 1 | S30: 2 | T30: 2.5 | U30: 1 | V30: 2.3 | W30: 2.5 | X30: 0.9 | Y30: 1.7 | Z30: 2.6 | AA30: 0.9 | AB30: 1.5 | AC30: 2.6
B31: ti [min] | C31: 26.9 | D31: 14.4 | E31: 10.1 | F31: 23.7 | G31: 12.7 | H31: 8.8 | I31: 23.8 | J31: 12.6 | K31: 8.7 | L31: 23.7 | M31: 13.5 | N31: 9 | O31: 23.5 | P31: 12.6 | Q31: 8.6 | R31: 24.4 | S31: 12.5 | T31: 9.4 | U31: 23.4 | V31: 12.7 | W31: 8.8 | X31: 22.3 | Y31: 12.2 | Z31: 8.4 | AA31: 21.4 | AB31: 11.5 | AC31: 8
B32: tp [min] | C32: 31.8 | D32: 17.4 | E32: 12 | F32: 27.1 | G32: 14.2 | H32: 9.9 | I32: 27 | J32: 14.7 | K32: 10 | L32: 26.9 | M32: 16 | N32: 11.3 | O32: 28.1 | P32: 15 | Q32: 10 | R32: 28.9 | S32: 14.8 | T32: 11 | U32: 26.6 | V32: 14.7 | W32: 10 | X32: 25.4 | Y32: 13.6 | Z32: 9.4 | AA32: 25.7 | AB32: 13.3 | AC32: 9.3
B33: Δt1/2 [min] | C33: 6.7 | D33: 4 | E33: 2.7 | F33: 7.3 | G33: 3.8 | H33: 2.6 | I33: 9.4 | J33: 4.7 | K33: 3.1 | L33: 9 | M33: 4 | N33: 3.1 | O33: 9.2 | P33: 4.5 | Q33: 3.1 | R33: 8.9 | S33: 4.5 | T33: 2.8 | U33: 9.2 | V33: 4.8 | W33: 3 | X33: 7.6 | Y33: 3.7 | Z33: 2.3 | AA33: 9.2 | AB33: 4.1 | AC33: 2.4
B34: tb [min] | C34: 40.3 | D34: 20.3 | E34: 14.2 | F34: 38.6 | G34: 19.9 | H34: 13.9 | I34: 41.2 | J34: 20.9 | K34: 14.2 | L34: 41.2 | M34: 20.6 | N34: 14.7 | O34: 41.7 | P34: 21.1 | Q34: 15 | R34: 42.3 | S34: 21.5 | T34: 15 | U34: 40.6 | V34: 22 | W34: 14.3 | X34: 38.2 | Y34: 19.6 | Z34: 13.3 | AA34: 41.9 | AB34: 21.8 | AC34: 13.1
B35: Di · 1003 | C35: 9.4 | D35: 54.3 | E35: 184.8 | F35: 9.2 | G35: 57.8 | H35: 174.3 | I35: 7.5 | J35: 52.7 | K35: 175.9 | L35: 8.4 | M35: 57 | N35: 143.8 | O35: 7.2 | P35: 52.3 | Q35: 149.1 | R35: 7 | S35: 53.5 | T35: 139.7 | U35: 8.5 | V35: 50.5 | W35: 171.1 | X35: 8.4 | Y35: 63.4 | Z35: 193.5 | AA35: 6.1 | AB35: 43.4 | AC35: 215.3
B36: Db · 1004 | C36: 9.4 | D36: 97.2 | E36: 498.5 | F36: 7.8 | G36: 96.1 | H36: 421.7 | I36: 4.6 | J36: 68 | K36: 346.1 | L36: 5.4 | M36: 94.6 | N36: 280.8 | O36: 4.4 | P36: 70.4 | Q36: 281.7 | R36: 4.5 | S36: 69 | T36: 312.6 | U36: 5.3 | V36: 62.5 | W36: 281.7 | X36: 6.6 | Y36: 87.3 | Z36: 562.1 | AA36: 3.4 | AB36: 56.7 | AC36: 559.6
B37: S · 1008 | C37: 27.9 | D37: 60.5 | E37: 150.9 | F37: 24 | G37: 62.9 | H37: 137.8 | I37: 17 | J37: 69 | K37: 161.6 | L37: 22.2 | M37: 77.1 | N37: 136.2 | O37: 17.8 | P37: 72.9 | Q37: 121.5 | R37: 17.1 | S37: 72.6 | T37: 106.2 | U37: 21.2 | V37: 74.6 | W37: 135.9 | X37: 19.8 | Y37: 59.2 | Z37: 172.9 | AA37: 13.7 | AB37: 44.2 | AC37: 203.1
... B39: Fi · 1005 | C39: 21.4 | D39: 40 | E39: 62.2 | F39: 15.9 | G39: 28.3 | H39: 38.5 | I39: 11 | J39: 23.2 | K39: 36.3 | L39: 12.3 | M39: 31.9 | N39: 32.3 | O39: 10.6 | P39: 22.7 | Q39: 26.8 | R39: 10.7 | S39: 21.7 | T39: 31.1 | U39: 12.4 | V39: 20.1 | W39: 35.7 | X39: 12.8 | Y39: 21.6 | Z39: 42.3 | AA39: 7.2 | AB39: 17.3 | AC39: 44.4

Sheet Biomass_quality_final
A1: Biomass_Type | B1: Heating_Rate | C1: Parameter | D1: Value | E1: Analysis_Type
A2: Pine wood 10 | B2: =IFERROR(__xludf.DUMMYFUNCTION("ARRAYFORMULA(IF(A2:A1001="""","""",IFERROR(VALUE(REGEXEXTRACT(TRIM(A2:A1001),""\d+$"")),"""")))"),10.0) -> 10 | C2: Na | D2: 0.007 | E2: XRF Ash analysis
A3: Pine wood 20 | B3: =IFERROR(__xludf.DUMMYFUNCTION("""COMPUTED_VALUE"""),20.0) -> 20 | C3: Na | D3: 0.007 | E3: XRF Ash analysis
A4: Pine wood 30 | B4: =IFERROR(__xludf.DUMMYFUNCTION("""COMPUTED_VALUE"""),30.0) -> 30 | C4: Na | D4: 0.007 | E4: XRF Ash analysis
A5: Kiwi 10 | B5: =IFERROR(__xludf.DUMMYFUNCTION("""COMPUTED_VALUE"""),10.0) -> 10 | C5: Na | D5: 0.072 | E5: XRF Ash analysis
A6: Kiwi 20 | B6: =IFERROR(__xludf.DUMMYFUNCTION("""COMPUTED_VALUE"""),20.0) -> 20 | C6: Na | D6: 0.072 | E6: XRF Ash analysis
A7: Kiwi 30 | B7: =IFERROR(__xludf.DUMMYFUNCTION("""COMPUTED_VALUE"""),30.0) -> 30 | C7: Na | D7: 0.072 | E7: XRF Ash analysis
A8: Kiwi N2 10 | B8: =IFERROR(__xludf.DUMMYFUNCTION("""COMPUTED_VALUE"""),10.0) -> 10 | C8: Na | D8: 0.077 | E8: XRF Ash analysis
A9: Kiwi N2 20 | B9: =IFERROR(__xludf.DUMMYFUNCTION("""COMPUTED_VALUE"""),20.0) -> 20 | C9: Na | D9: 0.077 | E9: XRF Ash analysis
A10: Kiwi N2 30 | B10: =IFERROR(__xludf.DUMMYFUNCTION("""COMPUTED_VALUE"""),30.0) -> 30 | C10: Na | D10: 0.077 | E10: XRF Ash analysis
A11: Kiwi N3 10 | B11: =IFERROR(__xludf.DUMMYFUNCTION("""COMPUTED_VALUE"""),10.0) -> 10 | C11: Na | D11: 0.13 | E11: XRF Ash analysis
A12: Kiwi N3 20 | B12: =IFERROR(__xludf.DUMMYFUNCTION("""COMPUTED_VALUE"""),20.0) -> 20 | C12: Na | D12: 0.13 | E12: XRF Ash analysis
A13: Kiwi N3 30 | B13: =IFERROR(__xludf.DUMMYFUNCTION("""COMPUTED_VALUE"""),30.0) -> 30 | C13: Na | D13: 0.13 | E13: XRF Ash analysis
A14: Gorse 10 | B14: =IFERROR(__xludf.DUMMYFUNCTION("""COMPUTED_VALUE"""),10.0) -> 10 | C14: Na | D14: 0.116 | E14: XRF Ash analysis
A15: Gorse 20 | B15: =IFERROR(__xludf.DUMMYFUNCTION("""COMPUTED_VALUE"""),20.0) -> 20 | C15: Na | D15: 0.116 | E15: XRF Ash analysis
A16: Gorse 30 | B16: =IFERROR(__xludf.DUMMYFUNCTION("""COMPUTED_VALUE"""),30.0) -> 30 | C16: Na | D16: 0.116 | E16: XRF Ash analysis
A17: Gorse N2 10 | B17: =IFERROR(__xludf.DUMMYFUNCTION("""COMPUTED_VALUE"""),10.0) -> 10 | C17: Na | D17: 0.009 | E17: XRF Ash analysis
A18: Gorse N2 20 | B18: =IFERROR(__xludf.DUMMYFUNCTION("""COMPUTED_VALUE"""),20.0) -> 20 | C18: Na | D18: 0.009 | E18: XRF Ash analysis
A19: Gorse N2 30 | B19: =IFERROR(__xludf.DUMMYFUNCTION("""COMPUTED_VALUE"""),30.0) -> 30 | C19: Na | D19: 0.009 | E19: XRF Ash analysis
A20: Gorse N3 10 | B20: =IFERROR(__xludf.DUMMYFUNCTION("""COMPUTED_VALUE"""),10.0) -> 10 | C20: Na | D20: 0.01 | E20: XRF Ash analysis
A21: Gorse N3 20 | B21: =IFERROR(__xludf.DUMMYFUNCTION("""COMPUTED_VALUE"""),20.0) -> 20 | C21: Na | D21: 0.01 | E21: XRF Ash analysis
A22: Gorse N3 30 | B22: =IFERROR(__xludf.DUMMYFUNCTION("""COMPUTED_VALUE"""),30.0) -> 30 | C22: Na | D22: 0.01 | E22: XRF Ash analysis
A23: Poultry 10 | B23: =IFERROR(__xludf.DUMMYFUNCTION("""COMPUTED_VALUE"""),10.0) -> 10 | C23: Na | D23: 0 | E23: XRF Ash analysis
A24: Poultry 20 | B24: =IFERROR(__xludf.DUMMYFUNCTION("""COMPUTED_VALUE"""),20.0) -> 20 | C24: Na | D24: 0 | E24: XRF Ash analysis
A25: Poultry 30 | B25: =IFERROR(__xludf.DUMMYFUNCTION("""COMPUTED_VALUE"""),30.0) -> 30 | C25: Na | D25: 0 | E25: XRF Ash analysis
A26: Pine wood 10 | B26: =IFERROR(__xludf.DUMMYFUNCTION("""COMPUTED_VALUE"""),10.0) -> 10 | C26: Mg | D26: 0.155 | E26: XRF Ash analysis
A27: Pine wood 20 | B27: =IFERROR(__xludf.DUMMYFUNCTION("""COMPUTED_VALUE"""),20.0) -> 20 | C27: Mg | D27: 0.155 | E27: XRF Ash analysis
A28: Pine wood 30 | B28: =IFERROR(__xludf.DUMMYFUNCTION("""COMPUTED_VALUE"""),30.0) -> 30 | C28: Mg | D28: 0.155 | E28: XRF Ash analysis
A29: Kiwi 10 | B29: =IFERROR(__xludf.DUMMYFUNCTION("""COMPUTED_VALUE"""),10.0) -> 10 | C29: Mg | D29: 0.08 | E29: XRF Ash analysis
A30: Kiwi 20 | B30: =IFERROR(__xludf.DUMMYFUNCTION("""COMPUTED_VALUE"""),20.0) -> 20 | C30: Mg | D30: 0.08 | E30: XRF Ash analysis
A31: Kiwi 30 | B31: =IFERROR(__xludf.DUMMYFUNCTION("""COMPUTED_VALUE"""),30.0) -> 30 | C31: Mg | D31: 0.08 | E31: XRF Ash analysis
A32: Kiwi N2 10 | B32: =IFERROR(__xludf.DUMMYFUNCTION("""COMPUTED_VALUE"""),10.0) -> 10 | C32: Mg | D32: 0.048 | E32: XRF Ash analysis
A33: Kiwi N2 20 | B33: =IFERROR(__xludf.DUMMYFUNCTION("""COMPUTED_VALUE"""),20.0) -> 20 | C33: Mg | D33: 0.048 | E33: XRF Ash analysis
A34: Kiwi N2 30 | B34: =IFERROR(__xludf.DUMMYFUNCTION("""COMPUTED_VALUE"""),30.0) -> 30 | C34: Mg | D34: 0.048 | E34: XRF Ash analysis
A35: Kiwi N3 10 | B35: =IFERROR(__xludf.DUMMYFUNCTION("""COMPUTED_VALUE"""),10.0) -> 10 | C35: Mg | D35: 0.068 | E35: XRF Ash analysis
A36: Kiwi N3 20 | B36: =IFERROR(__xludf.DUMMYFUNCTION("""COMPUTED_VALUE"""),20.0) -> 20 | C36: Mg | D36: 0.068 | E36: XRF Ash analysis
A37: Kiwi N3 30 | B37: =IFERROR(__xludf.DUMMYFUNCTION("""COMPUTED_VALUE"""),30.0) -> 30 | C37: Mg | D37: 0.068 | E37: XRF Ash analysis
A38: Gorse 10 | B38: =IFERROR(__xludf.DUMMYFUNCTION("""COMPUTED_VALUE"""),10.0) -> 10 | C38: Mg | D38: 0.072 | E38: XRF Ash analysis
A39: Gorse 20 | B39: =IFERROR(__xludf.DUMMYFUNCTION("""COMPUTED_VALUE"""),20.0) -> 20 | C39: Mg | D39: 0.072 | E39: XRF Ash analysis
A40: Gorse 30 | B40: =IFERROR(__xludf.DUMMYFUNCTION("""COMPUTED_VALUE"""),30.0) -> 30 | C40: Mg | D40: 0.072 | E40: XRF Ash analysis
...

Sheet india_bioenergy
A1: Country | B1: Year | C1: Bioenergy_Value | D1: Growth_Rate | E1: India_Selected_Country_Share
A2: India | B2: 2013 | C2: 6682214 | D2: 0 | E2: =C2 / VLOOKUP(B2, Worlds!A:B, 2, FALSE) -> 0.31649829
A3: India | B3: 2014 | C3: 6842407 | D3: =(C3-C2)/C2 -> 0.023973042 | E3: =C3 / VLOOKUP(B3, Worlds!A:B, 2, FALSE) -> 0.31528207
A4: India | B4: 2015 | C4: 6992891 | D4: =(C4-C3)/C3 -> 0.021992846 | E4: =C4 / VLOOKUP(B4, Worlds!A:B, 2, FALSE) -> 0.31936692
A5: India | B5: 2016 | C5: 7275800 | D5: =(C5-C4)/C4 -> 0.040456658 | E5: =C5 / VLOOKUP(B5, Worlds!A:B, 2, FALSE) -> 0.3256689
A6: India | B6: 2017 | C6: 7643565 | D6: =(C6-C5)/C5 -> 0.050546332 | E6: =C6 / VLOOKUP(B6, Worlds!A:B, 2, FALSE) -> 0.33153468
A7: India | B7: 2018 | C7: 7840193 | D7: =(C7-C6)/C6 -> 0.025724646 | E7: =C7 / VLOOKUP(B7, Worlds!A:B, 2, FALSE) -> 0.32766488
A8: India | B8: 2019 | C8: 7903277 | D8: =(C8-C7)/C7 -> 0.0080462305 | E8: =C8 / VLOOKUP(B8, Worlds!A:B, 2, FALSE) -> 0.32979769
A9: India | B9: 2020 | C9: 8087310 | D9: =(C9-C8)/C8 -> 0.023285657 | E9: =C9 / VLOOKUP(B9, Worlds!A:B, 2, FALSE) -> 0.34161693
A10: India | B10: 2021 | C10: 8311518 | D10: =(C10-C9)/C9 -> 0.027723433 | E10: =C10 / VLOOKUP(B10, Worlds!A:B, 2, FALSE) -> 0.33854105
A11: India | B11: 2022 | C11: 8605122 | D11: =(C11-C10)/C10 -> 0.035324955 | E11: =C11 / VLOOKUP(B11, Worlds!A:B, 2, FALSE) -> 0.35000112
A12: India | B12: 2023 | C12: 8605125 | D12: =(C12-C11)/C11 -> 3.4862957e-07 | E12: =C12 / VLOOKUP(B12, Worlds!A:B, 2, FALSE) -> 0.34314873

Sheet Worlds
A1: Year | B1: World_total
A2: 2000 | B2: =SUMIF(world_bioenergy!B:B, A2, world_bioenergy!C:C) -> 15356736
A3: 2001 | B3: =SUMIF(world_bioenergy!B:B, A3, world_bioenergy!C:C) -> 15237485
A4: 2002 | B4: =SUMIF(world_bioenergy!B:B, A4, world_bioenergy!C:C) -> 15637859
A5: 2003 | B5: =SUMIF(world_bioenergy!B:B, A5, world_bioenergy!C:C) -> 16427535
A6: 2004 | B6: =SUMIF(world_bioenergy!B:B, A6, world_bioenergy!C:C) -> 17000758
A7: 2005 | B7: =SUMIF(world_bioenergy!B:B, A7, world_bioenergy!C:C) -> 17526894
A8: 2006 | B8: =SUMIF(world_bioenergy!B:B, A8, world_bioenergy!C:C) -> 18165892
A9: 2007 | B9: =SUMIF(world_bioenergy!B:B, A9, world_bioenergy!C:C) -> 19172886
A10: 2008 | B10: =SUMIF(world_bioenergy!B:B, A10, world_bioenergy!C:C) -> 19374640
A11: 2009 | B11: =SUMIF(world_bioenergy!B:B, A11, world_bioenergy!C:C) -> 19185813
A12: 2010 | B12: =SUMIF(world_bioenergy!B:B, A12, world_bioenergy!C:C) -> 19973891
A13: 2011 | B13: =SUMIF(world_bioenergy!B:B, A13, world_bioenergy!C:C) -> 20005202
... A25: 2023 | B25: =SUMIF(world_bioenergy!B:B, A25, world_bioenergy!C:C) -> 25076954

Sheet india_biomass_production
A1: Total Biomass Available (thousand tonnes) in India
A2: States | B2: Wheat | C2: Rice | D2: Maize | E2: Bajra | F2: Sugarcane | G2: Groundnut | H2: Rapeseed Mustard | I2: Arhar/Tur | J2: Total Crops
A3: Andaman and Nicobar | B3: null | C3: 19.7 | D3: 1 | E3: null | F3: 0.1 | G3: null | H3: null | I3: null | J3: 201
A4: Andhra Pradesh | B4: 0.1 | C4: 14407 | D4: 4248 | E4: 164 | F4: 394 | G4: 1619 | H4: 3 | I4: 278 | J4: 40012
A5: Arunachal Pradesh | B5: 14.2 | C5: 322 | D5: null | E5: null | F5: 2.1 | G5: null | H5: null | I5: null | J5: 751
A6: Assam | B6: 43.6 | C6: 7768 | D6: 212.5 | E6: null | F6: 56.5 | G6: null | H6: 344.6 | I6: 14.2 | J6: 12571
A7: Bihar | B7: 10096 | C7: 11571.6 | D7: 7289 | E7: 12 | F7: 646.6 | G7: 1.7 | H7: 174 | I7: 93 | J7: 32572
A8: Chandigarh | B8: 4.6 | C8: 0.1 | D8: 0.1 | E8: null | F8: null | G8: null | H8: null | I8: null | J8: 5
A9: Chhattisgarh | B9: 268 | C9: 10962 | D9: 599.5 | E9: 0.2 | F9: 3.9 | G9: 95.8 | H9: 41.4 | I9: 97.8 | J9: 12990
A10: Dadra & Nagar Haveli, and Daman &Diu | B10: 0.6 | C10: 41.5 | D10: 0.2 | E10: 1.6 | F10: 2.6 | G10: null | H10: null | I10: 4.5 | J10: 53.3
A11: Goa | B11: null | C11: 157.5 | D11: null | E11: null | F11: 2 | G11: 6.5 | H11: null | I11: null | J11: 451.7
A12: Gujarat | B12: 4904.8 | C12: 2785.1 | D12: 1659 | E12: 2421.8 | F12: 555.9 | G12: 6878 | H12: 618.4 | I12: 945.5 | J12: 50235.7
A13: Haryana | B13: 20024.4 | C13: 5985.5 | D13: 57.5 | E13: 2025.1 | F13: 371.7 | G13: 8.1 | H13: 1518.3 | I13: 26.5 | J13: 36238.6
A14: Himachal Pradesh | B14: 922.3 | C14: 166.5 | D14: 1459 | E14: 0.2 | F14: 2 | G14: 0.1 | H14: 6.4 | I14: null | J14: 2743.3
A15: Jammu and Kashmir | B15: 1040.2 | C15: 865.9 | D15: 1221.2 | E15: 16.5 | F15: null | G15: null | H15: 56.2 | I15: null | J15: 3240.2
A16: Jharkhand | B16: 340.4 | C16: 3479.3 | D16: 753.3 | E16: null | F16: null | G16: null | H16: 68.2 | I16: 343.3 | J16: 5311
A17: Karnataka | B17: 311.7 | C17: 4413 | D17: 9381 | E17: 644.3 | F17: 1630.5 | G17: 1111.6 | H17: 1 | I17: 2140.6 | J17: 34093.6
A18: Kerala | B18: null | C18: 739.3 | D18: 0.1 | E18: null | F18: 0.6 | G18: 1.1 | H18: null | I18: 3.8 | J18: 8584.1
A19: Madhya Pradesh | B19: 31555.6 | C19: 5131.5 | D19: 5316.4 | E19: 1319.4 | F19: 187.8 | G19: 756.5 | H19: 1168.6 | I19: 1298.8 | J19: 70233.1
A20: Maharashtra | B20: 3048.1 | C20: 4456 | D20: 6231.7 | E20: 1579.7 | F20: 3433.8 | G20: 843.1 | H20: 6 | I20: null | J20: 52540.1
A21: Manipur | B21: 10 | C21: 803.9 | D21: 135.5 | E21: null | F21: 17.1 | G21: 6.5 | H21: 42.4 | I21: 1.4 | J21: 1143.8
A22: Meghalaya | B22: 1.6 | C22: 455.1 | D22: 95.4 | E22: null | F22: null | G22: null | H22: 16.7 | I22: 4.2 | J22: 1373.3
A23: Mizoram | B23: null | C23: 92.6 | D23: 22.1 | E23: null | F23: 2.4 | G23: null0 | H23: 1.1 | I23: 0.9 | J23: 134.1
A24: Nagaland | B24: 9.1 | C24: 684 | D24: 319.3 | E24: 1.8 | F24: 21.3 | G24: 2.3 | H24: 48.9 | I24: 13.4 | J24: 1377.6
A25: Odisha | B25: 0.4 | C25: 11110.3 | D25: 332.4 | E25: null | F25: 1.9 | G25: 114.4 | H25: 4.6 | I25: null | J25: 11839.2
A26: Puducherry | B26: null | C26: 76 | D26: null | E26: 0.1 | F26: 10.1 | G26: 1.9 | H26: null | I26: 1 | J26: 122.6
A27: Punjab | B27: 30925.8 | C27: 18921.5 | D27: 1013.1 | E27: null | F27: 366.2 | G27: 5.6 | H27: 81.4 | I27: 12.1 | J27: 53003.9
A28: Rajasthan | B28: 20609.2 | C28: 636.7 | D28: 3315.4 | E28: 9767.5 | F28: 25.5 | G28: 2656.3 | H28: 6359.4 | I28: 36.2 | J28: 59504.1
A29: Sikkim | B29: 0.7 | C29: 29.6 | D29: 157.3 | E29: null | F29: null | G29: null | H29: null | I29: null | J29: 228.6
A30: Tamil Nadu | B30: null | C30: 18154.3 | D30: 10620.2 | E30: 711 | F30: 1027.5 | G30: 1908.6 | H30: 0.2 | I30: 254.3 | J30: 52141.3
A31: Telangana | B31: 23.9 | C31: 10835.7 | D31: 7834.7 | E31: 51.2 | F31: 183.7 | G31: 1033.7 | H31: 5.1 | I31: 734.6 | J31: 33623.6
A32: Tripura | B32: 0.6 | C32: 1345.8 | D32: 21.5 | E32: null | F32: 2.2 | G32: 2.4 | H32: 7.3 | I32: 7 | J32: 1413.3
A33: Uttar Pradesh | B33: 65194.1 | C33: 23005.1 | D33: 3571.3 | E33: 4656.6 | F33: 8561.7 | G33: 210.9 | H33: 1751.9 | I33: 903.6 | J33: 124692.8
A34: Uttarakhand | B34: 1639.4 | C34: 977.4 | D34: 91.4 | E34: null | F34: 295.8 | G34: 2.7 | H34: 20.4 | I34: 7.8 | J34: 3552.2
A35: West Bengal | B35: 1348.7 | C35: 24139.1 | D35: 3780.2 | E35: 0.1 | F35: 81.5 | G35: 443.5 | H35: 1233 | I35: 11.6 | J35: 47506.4
A36: Total | B36: 192338.9 | C36: 184538.8 | D36: 69739.4 | E36: 23481.3 | F36: 17887.1 | G36: 17710.2 | H36: 13879.7 | I36: 7234.3 | J36: 754484.9
A39: Surplus Biomass Residue (Thousand Tonnes) in India
A41: States | B41: Rice | C41: Wheat | D41: Maize | E41: Sugarcane | F41: Arhar/Tur | G41: Bajra | H41: Rapeseed Mustard | I41: Groundnut | J41: Total | K41: Power Potential (MW)
A42: Andaman and Nicobar | B42: 3.3 | C42: null | D42: 0.2 | E42: null | F42: null | G42: null | H42: null | I42: null | J42: 131.7 | K42: 18.1
A43: Andhra Pradesh | B43: 2571 | C43: null | D43: 2389 | E43: 394 | F43: 195 | G43: 31 | H43: 1.5 | I43: 194 | J43: 17093 | K43: 1999.5
...

Sheet India_biomass_long_v2
A1: States_and_UT | B1: Crop | C1: Biomass_value
A2: Andaman and Nicobar | B2: Wheat
A3: Andaman and Nicobar | B3: Rice | C3: 19.7
A4: Andaman and Nicobar | B4: Maize | C4: 1
A5: Andaman and Nicobar | B5: Bajra
A6: Andaman and Nicobar | B6: Sugarcane | C6: 0.1
A7: Andaman and Nicobar | B7: Groundnut
A8: Andaman and Nicobar | B8: Rapeseed Mustard
A9: Andaman and Nicobar | B9: Arhar/Tur
A10: Andhra Pradesh | B10: Wheat | C10: 0.1
A11: Andhra Pradesh | B11: Rice | C11: 14407
A12: Andhra Pradesh | B12: Maize | C12: 4248
A13: Andhra Pradesh | B13: Bajra | C13: 164
A14: Andhra Pradesh | B14: Sugarcane | C14: 394
A15: Andhra Pradesh | B15: Groundnut | C15: 1619
A16: Andhra Pradesh | B16: Rapeseed Mustard | C16: 3
A17: Andhra Pradesh | B17: Arhar/Tur | C17: 278
A18: Arunachal Pradesh | B18: Wheat | C18: 14.2
A19: Arunachal Pradesh | B19: Rice | C19: 322
A20: Arunachal Pradesh | B20: Maize
A21: Arunachal Pradesh | B21: Bajra
A22: Arunachal Pradesh | B22: Sugarcane | C22: 2.1
A23: Arunachal Pradesh | B23: Groundnut
A24: Arunachal Pradesh | B24: Rapeseed Mustard
A25: Arunachal Pradesh | B25: Arhar/Tur
A26: Assam | B26: Wheat | C26: 43.6
A27: Assam | B27: Rice | C27: 7768
A28: Assam | B28: Maize | C28: 212.5
A29: Assam | B29: Bajra
A30: Assam | B30: Sugarcane | C30: 56.5
A31: Assam | B31: Groundnut
A32: Assam | B32: Rapeseed Mustard | C32: 344.6
A33: Assam | B33: Arhar/Tur | C33: 14.2
A34: Bihar | B34: Wheat | C34: 10096
A35: Bihar | B35: Rice | C35: 11571.6
A36: Bihar | B36: Maize | C36: 7289
A37: Bihar | B37: Bajra | C37: 12
A38: Bihar | B38: Sugarcane | C38: 646.6
A39: Bihar | B39: Groundnut | C39: 1.7
A40: Bihar | B40: Rapeseed Mustard | C40: 174
...

Sheet KPI
A1: KPI | B1: Value
A2: Total India Biomass | B2: =SUM(india_biomass_production!C:C) -> 435822.22
A3: Avg Biomass Quality | B3: =AVERAGE(Biomass_quality_final!D:D) -> 40.00552
A4: India Global Rank | B4: 3

Sheet world_bioenergy
A1: Country | B1: Year | C1: Value | D1: World_comparision_with_India
A2: Brazil | B2: 2000 | C2: 2092859 | D2: {=C2 / XLOOKUP(B2, india_reference!A:A, india_reference!B:B)} -> 0.39736061
A3: Brazil | B3: 2001 | C3: 2202556 | D3: {=C3 / XLOOKUP(B3, india_reference!A:A, india_reference!B:B)} -> 0.41196268
A4: Brazil | B4: 2002 | C4: 2399202 | D4: {=C4 / XLOOKUP(B4, india_reference!A:A, india_reference!B:B)} -> 0.44634373
A5: Brazil | B5: 2003 | C5: 2676386 | D5: {=C5 / XLOOKUP(B5, india_reference!A:A, india_reference!B:B)} -> 0.49185207
A6: Brazil | B6: 2004 | C6: 2805291 | D6: {=C6 / XLOOKUP(B6, india_reference!A:A, india_reference!B:B)} -> 0.50458041
A7: Brazil | B7: 2005 | C7: 2937378 | D7: {=C7 / XLOOKUP(B7, india_reference!A:A, india_reference!B:B)} -> 0.52012733
A8: Brazil | B8: 2006 | C8: 3140208 | D8: {=C8 / XLOOKUP(B8, india_reference!A:A, india_reference!B:B)} -> 0.54286256
A9: Brazil | B9: 2007 | C9: 3509780 | D9: {=C9 / XLOOKUP(B9, india_reference!A:A, india_reference!B:B)} -> 0.59270985
A10: Brazil | B10: 2008 | C10: 3238897 | D10: {=C10 / XLOOKUP(B10, india_reference!A:A, india_reference!B:B)} -> 0.53908014
A11: Brazil | B11: 2009 | C11: 3101543 | D11: {=C11 / XLOOKUP(B11, india_reference!A:A, india_reference!B:B)} -> 0.5082916
A12: Brazil | B12: 2010 | C12: 3376495 | D12: {=C12 / XLOOKUP(B12, india_reference!A:A, india_reference!B:B)} -> 0.53725404
A13: Brazil | B13: 2011 | C13: 3255430 | D13: {=C13 / XLOOKUP(B13, india_reference!A:A, india_reference!B:B)} -> 0.51109679
... A193: United States of America | B193: 2023 | C193: 4102686 | D193: {=C193 / XLOOKUP(B193, india_reference!A:A, india_reference!B:B)} -> 0.47677239

Sheet india_reference
A1: 2000 | B1: 5266901
A2: 2001 | B2: 5346494
A3: 2002 | B3: 5375234
A4: 2003 | B4: 5441445
A5: 2004 | B5: 5559651
A6: 2005 | B6: 5647421
A7: 2006 | B7: 5784536
A8: 2007 | B8: 5921582
A9: 2008 | B9: 6008192
A10: 2009 | B10: 6101897
A11: 2010 | B11: 6284727
A12: 2011 | B12: 6369498
... A24: 2023 | B24: 8605125
